# 🐛 **Bug Fix Summary - UnboundLocalError**

## ✅ **ISSUE RESOLVED**

### **🐛 Bug Description:**
```
UnboundLocalError: cannot access local variable 'traffic_conditions' where it is not associated with a value
```

**Location**: `app.py` line 734 in the `main()` function

### **🔍 Root Cause:**
The `traffic_conditions` variable was only being initialized inside the conditional block:
```python
if live_traffic_enabled and sp and ep:
    # ... traffic data fetching logic ...
    if traffic_data:
        traffic_conditions = traffic_manager.get_traffic_conditions(traffic_data)
    else:
        traffic_conditions = None
```

However, it was being used outside this block in the ETA calculation:
```python
details = predict_travel_with_details(
    # ... other parameters ...
    traffic_data=traffic_conditions  # ❌ Error: traffic_conditions not defined
)
```

### **🔧 Fix Applied:**
Added proper initialization of `traffic_conditions` at the beginning of the traffic data section:

```python
# Get traffic data if enabled
traffic_data = None
traffic_conditions = None  # ✅ Initialize traffic_conditions

if live_traffic_enabled and sp and ep:
    # ... existing logic ...
```

### **✅ Verification:**
- ✅ **App imports successfully** without errors
- ✅ **All 16 traffic integration tests** pass
- ✅ **No regression** in functionality
- ✅ **Variable properly scoped** for all code paths

### **🎯 Impact:**
- **Before**: App crashes with UnboundLocalError when traffic integration is enabled
- **After**: App runs smoothly with proper traffic integration functionality

### **📁 Files Modified:**
- `app.py` - Added `traffic_conditions = None` initialization

### **🧪 Testing:**
```bash
# Verify app imports
python -c "import app; print('✅ App imports successfully')"

# Verify tests pass
python tests/test_traffic_integration.py
```

**The bug is now completely resolved and the app should run without any UnboundLocalError issues!** 🎉
